Workbook

Sheet INVENTORY MANAGEMENT
A2: SL. No. | B2: PRODUCT | C2: OPENING STOCK | E2: Opening STOCK VALUE | G2: NEW STOCK | H2: CLOSING STOCK | J2: SALE | K2: Closing STOCK VALUE | M2: EMPTY BOTTLE
A3: 1 | B3: CEASAR BRANDY | C3: 1000 ml | E3: =(('[1]PURCHASE COST'!D2/12)+(('[1]PURCHASE COST'!D2/12)*3.87%))*D3 -> 0 | F3: =SUM(E3:E7) -> 3531.303 | H3: 1000 ml | L3: =K3+K4+K5+K6+K7 -> 3391.9095 | M3: =D3-I3 -> 0
C4: 750 ml | D4: 3 | E4: =(('[1]PURCHASE COST'!D3/12)+(('[1]PURCHASE COST'!D3/12)*3.87%))*D4 -> 3484.8385 | H4: 750 ml | I4: 2 | J4: =(D4+G4)-I4 -> 1 | K4: =(('[1]PURCHASE COST'!D3/12)+(('[1]PURCHASE COST'!D3/12)*3.87%))*I4 -> 2323.2257 | M4: =D4-I4 -> 1
C5: 500 ml | E5: =(('[1]PURCHASE COST'!D4/18)+(('[1]PURCHASE COST'!D4/18)*3.87%))*D5 -> 0 | H5: 500 ml | J5: =(D5+G5)-I5 -> 0 | K5: =(('[1]PURCHASE COST'!D4/18)+(('[1]PURCHASE COST'!D4/18)*3.87%))*I5 -> 0 | M5: =D5-I5 -> 0
C6: 375 ml | E6: =(('[1]PURCHASE COST'!D5/24)+(('[1]PURCHASE COST'!D5/24)*3.87%))*D6 -> 0 | H6: 375 ml | J6: =(D6+G6)-I6 -> 0 | K6: =(('[1]PURCHASE COST'!D5/24)+(('[1]PURCHASE COST'!D5/24)*3.87%))*I6 -> 0 | M6: =D6-I6 -> 0
C7: 60 ml | D7: 0.5 | E7: =((('[1]PURCHASE COST'!D3/12)+(('[1]PURCHASE COST'!D3/12)*3.87%))/12.5)*D7 -> 46.464513 | H7: 60 ml | I7: 11.5 | J7: =((((D4+G4)-I4)*12.5)+D7)-I7 -> 1.5 | K7: =((('[1]PURCHASE COST'!D3/12)+(('[1]PURCHASE COST'!D3/12)*3.87%))/12.5)*I7 -> 1068.6838
A8: 2 | B8: M.C BRANDY | C8: 1000 ml | D8: 115 | E8: =(('[1]PURCHASE COST'!D7/9)+(('[1]PURCHASE COST'!D7/9)*3.87%))*D8 -> 89189.707 | F8: =SUM(E8:E12) -> 103036.73 | H8: 1000 ml | I8: 110 | K8: =(('[1]PURCHASE COST'!D7/9)+(('[1]PURCHASE COST'!D7/9)*3.87%))*I8 -> 85311.893 | L8: =K8+K9+K10+K11+K12 -> 99252.926 | M8: =D8-I8 -> 5
C9: 750 ml | E9: =(('[1]PURCHASE COST'!D8/12)+(('[1]PURCHASE COST'!D8/12)*3.87%))*D9 -> 0 | H9: 750 ml | J9: =(D9+G9)-I9 -> 0 | K9: =(('[1]PURCHASE COST'!D8/12)+(('[1]PURCHASE COST'!D8/12)*3.87%))*I9 -> 0 | M9: =D9-I9 -> 0
C10: 500 ml | D10: 35 | E10: =(('[1]PURCHASE COST'!D9/18)+(('[1]PURCHASE COST'!D9/18)*3.87%))*D10 -> 13329.983 | H10: 500 ml | I10: 35 | J10: =(D10+G10)-I10 -> 0 | K10: =(('[1]PURCHASE COST'!D9/18)+(('[1]PURCHASE COST'!D9/18)*3.87%))*I10 -> 13329.983 | M10: =D10-I10 -> 0
C11: 375 ml | D11: 40 | E11: =(('[1]PURCHASE COST'!D10/24)+(('[1]PURCHASE COST'!D10/24)*3.87%))*D11 -> 0 | H11: 375 ml | I11: 39 | J11: =(D11+G11)-I11 -> 1 | K11: =(('[1]PURCHASE COST'!D10/24)+(('[1]PURCHASE COST'!D10/24)*3.87%))*I11 -> 0 | M11: =D11-I11 -> 1
C12: 60 ml | D12: 11 | E12: =((('[1]PURCHASE COST'!D7/9)+(('[1]PURCHASE COST'!D7/9)*3.87%))/16.5)*D12 -> 517.04178 | H12: 60 ml | I12: 13 | J12: =((((D8+G8)-I8)*16.5)+D12)-I12 -> 80.5 | K12: =((('[1]PURCHASE COST'!D7/9)+(('[1]PURCHASE COST'!D7/9)*3.87%))/16.5)*I12 -> 611.04937 | M12: =D12-I12 -> -2
A13: 3 | B13: MGM ORANGE VODKA | C13: 1000 ml | D13: 118 | E13: =(('[1]PURCHASE COST'!D12/9)+(('[1]PURCHASE COST'!D12/9)*3.87%))*D13 -> 87430.841 | F13: =SUM(E13:E17) -> 89899.38 | H13: 1000 ml | I13: 113 | K13: =(('[1]PURCHASE COST'!D12/9)+(('[1]PURCHASE COST'!D12/9)*3.87%))*I13 -> 83726.145 | L13: =K13+K14+K15+K16+K17 -> 86688.643 | M13: =D13-I13 -> 5
C14: 750 ml | E14: =(('[1]PURCHASE COST'!D13/12)+(('[1]PURCHASE COST'!D13/12)*3.87%))*D14 -> 0 | H14: 750 ml | J14: =(D14+G14)-I14 -> 0 | K14: =(('[1]PURCHASE COST'!D13/12)+(('[1]PURCHASE COST'!D13/12)*3.87%))*I14 -> 0 | M14: =D14-I14 -> 0
C15: 500 ml | E15: =(('[1]PURCHASE COST'!D14/18)+(('[1]PURCHASE COST'!D14/18)*3.87%))*D15 -> 0 | H15: 500 ml | J15: =(D15+G15)-I15 -> 0 | K15: =(('[1]PURCHASE COST'!D14/18)+(('[1]PURCHASE COST'!D14/18)*3.87%))*I15 -> 0 | M15: =D15-I15 -> 0
C16: 375 ml | D16: 8 | E16: =(('[1]PURCHASE COST'!D15/24)+(('[1]PURCHASE COST'!D15/24)*3.87%))*D16 -> 2423.6333 | H16: 375 ml | I16: 8 | J16: =(D16+G16)-I16 -> 0 | K16: =(('[1]PURCHASE COST'!D15/24)+(('[1]PURCHASE COST'!D15/24)*3.87%))*I16 -> 2423.6333 | M16: =D16-I16 -> 0
C17: 60 ml | D17: 1 | E17: =((('[1]PURCHASE COST'!D12/9)+(('[1]PURCHASE COST'!D12/9)*3.87%))/16.5)*D17 -> 44.905414 | H17: 60 ml | I17: 12 | J17: =((((D13+G13)-I13)*16.5)+D17)-I17 -> 71.5 | K17: =((('[1]PURCHASE COST'!D12/9)+(('[1]PURCHASE COST'!D12/9)*3.87%))/16.5)*I17 -> 538.86497
A18: 4 | B18: MANSION HOUSE BRANDY | C18: 1000 ml | D18: 18 | E18: =(('[1]PURCHASE COST'!D17/9)+(('[1]PURCHASE COST'!D17/9)*3.87%))*D18 -> 17117.776 | F18: =SUM(E18:E22) -> 33637.609 | H18: 1000 ml | I18: 18 | K18: =(('[1]PURCHASE COST'!D17/9)+(('[1]PURCHASE COST'!D17/9)*3.87%))*I18 -> 17117.776 | L18: =K18+K19+K20+K21+K22 -> 33090.07 | M18: =D18-I18 -> 0
C19: 750 ml | E19: =(('[1]PURCHASE COST'!D18/12)+(('[1]PURCHASE COST'!D18/12)*3.87%))*D19 -> 0 | H19: 750 ml | J19: =(D19+G19)-I19 -> 0 | K19: =(('[1]PURCHASE COST'!D18/12)+(('[1]PURCHASE COST'!D18/12)*3.87%))*I19 -> 0 | M19: =D19-I19 -> 0
C20: 500 ml | D20: 14 | E20: =(('[1]PURCHASE COST'!D19/18)+(('[1]PURCHASE COST'!D19/18)*3.87%))*D20 -> 6980.064 | H20: 500 ml | I20: 14 | J20: =(D20+G20)-I20 -> 0 | K20: =(('[1]PURCHASE COST'!D19/18)+(('[1]PURCHASE COST'!D19/18)*3.87%))*I20 -> 6980.064 | M20: =D20-I20 -> 0
C21: 375 ml | D21: 19 | E21: =(('[1]PURCHASE COST'!D20/24)+(('[1]PURCHASE COST'!D20/24)*3.87%))*D21 -> 8732.8702 | H21: 375 ml | I21: 19 | J21: =(D21+G21)-I21 -> 0 | K21: =(('[1]PURCHASE COST'!D20/24)+(('[1]PURCHASE COST'!D20/24)*3.87%))*I21 -> 8732.8702 | M21: =D21-I21 -> 0
C22: 60 ml | D22: 14 | E22: =((('[1]PURCHASE COST'!D17/9)+(('[1]PURCHASE COST'!D17/9)*3.87%))/16.5)*D22 -> 806.89853 | H22: 60 ml | I22: 4.5 | J22: =((((D18+G18)-I18)*16.5)+D22)-I22 -> 9.5 | K22: =((('[1]PURCHASE COST'!D17/9)+(('[1]PURCHASE COST'!D17/9)*3.87%))/16.5)*I22 -> 259.36024
A23: 5 | B23: OLD CASK RUM | C23: 1000 ml | E23: =(('[1]PURCHASE COST'!D22/9)+(('[1]PURCHASE COST'!D22/9)*3.87%))*D23 -> 0 | F23: =SUM(E23:E27) -> 1217.867 | H23: 1000 ml | J23: =(D23+G23)-I23 -> 0 | K23: =(('[1]PURCHASE COST'!D22/9)+(('[1]PURCHASE COST'!D22/9)*3.87%))*I23 -> 0 | L23: =K23+K24+K25+K26+K27 -> 1217.867 | M23: =D23-I23 -> 0
C24: 750 ml | E24: =(('[1]PURCHASE COST'!D23/12)+(('[1]PURCHASE COST'!D23/12)*3.87%))*D24 -> 0 | H24: 750 ml | J24: =(D24+G24)-I24 -> 0 | K24: =(('[1]PURCHASE COST'!D23/12)+(('[1]PURCHASE COST'!D23/12)*3.87%))*I24 -> 0 | M24: =D24-I24 -> 0
C25: 500 ml | D25: 3 | E25: =(('[1]PURCHASE COST'!D24/18)+(('[1]PURCHASE COST'!D24/18)*3.87%))*D25 -> 1125.2583 | H25: 500 ml | I25: 3 | J25: =(D25+G25)-I25 -> 0 | K25: =(('[1]PURCHASE COST'!D24/18)+(('[1]PURCHASE COST'!D24/18)*3.87%))*I25 -> 1125.2583 | M25: =D25-I25 -> 0
C26: 375 ml | E26: =(('[1]PURCHASE COST'!D25/24)+(('[1]PURCHASE COST'!D25/24)*3.87%))*D26 -> 0 | H26: 375 ml | J26: =(D26+G26)-I26 -> 0 | K26: =(('[1]PURCHASE COST'!D25/24)+(('[1]PURCHASE COST'!D25/24)*3.87%))*I26 -> 0 | M26: =D26-I26 -> 0
C27: 60 ml | D27: 2 | E27: =((('[1]PURCHASE COST'!D22/9)+(('[1]PURCHASE COST'!D22/9)*3.87%))/16.5)*D27 -> 92.608673 | H27: 60 ml | I27: 2 | J27: =((((D23+G23)-I23)*16.5)+D27)-I27 -> 0 | K27: =((('[1]PURCHASE COST'!D22/9)+(('[1]PURCHASE COST'!D22/9)*3.87%))/16.5)*I27 -> 92.608673
A28: 6 | B28: CR. NEPOLEAN BRANDY | C28: 1000 ml | D28: 33 | E28: =(('[1]PURCHASE COST'!D27/9)+(('[1]PURCHASE COST'!D27/9)*3.87%))*D28 -> 28259.565 | F28: =SUM(E28:E32) -> 28337.415 | H28: 1000 ml | I28: 32 | J28: =(D28+G28)-I28 -> 1 | K28: =(('[1]PURCHASE COST'!D27/9)+(('[1]PURCHASE COST'!D27/9)*3.87%))*I28 -> 27403.214 | L28: =K28+K29+K30+K31+K32 -> 27922.214 | M28: =D28-I28 -> 1
C29: 750 ml | E29: =(('[1]PURCHASE COST'!D28/12)+(('[1]PURCHASE COST'!D28/12)*3.87%))*D29 -> 0 | H29: 750 ml | J29: =(D29+G29)-I29 -> 0 | K29: =(('[1]PURCHASE COST'!D28/12)+(('[1]PURCHASE COST'!D28/12)*3.87%))*I29 -> 0 | M29: =D29-I29 -> 0
C30: 500 ml | E30: =(('[1]PURCHASE COST'!D29/18)+(('[1]PURCHASE COST'!D29/18)*3.87%))*D30 -> 0 | H30: 500 ml | J30: =(D30+G30)-I30 -> 0 | K30: =(('[1]PURCHASE COST'!D29/18)+(('[1]PURCHASE COST'!D29/18)*3.87%))*I30 -> 0 | M30: =D30-I30 -> 0
C31: 375 ml | E31: =(('[1]PURCHASE COST'!D30/24)+(('[1]PURCHASE COST'!D30/24)*3.87%))*D31 -> 0 | H31: 375 ml | J31: =(D31+G31)-I31 -> 0 | K31: =(('[1]PURCHASE COST'!D30/24)+(('[1]PURCHASE COST'!D30/24)*3.87%))*I31 -> 0 | M31: =D31-I31 -> 0
C32: 60 ml | D32: 1.5 | E32: =((('[1]PURCHASE COST'!D27/9)+(('[1]PURCHASE COST'!D27/9)*3.87%))/16.5)*D32 -> 77.85004 | H32: 60 ml | I32: 10 | J32: =((((D28+G28)-I28)*16.5)+D32)-I32 -> 8 | K32: =((('[1]PURCHASE COST'!D27/9)+(('[1]PURCHASE COST'!D27/9)*3.87%))/16.5)*I32 -> 519.00027
A33: 7 | B33: HONEY BEE BRANDY | C33: 1000 ml | D33: 24 | E33: =(('[1]PURCHASE COST'!D32/9)+(('[1]PURCHASE COST'!D32/9)*3.87%))*D33 -> 18613.504 | F33: =SUM(E33:E37) -> 26742.092 | H33: 1000 ml | I33: 23 | J33: =(D33+G33)-I33 -> 1 | K33: =(('[1]PURCHASE COST'!D32/9)+(('[1]PURCHASE COST'!D32/9)*3.87%))*I33 -> 17837.941 | L33: =K33+K34+K35+K36+K37 -> 26131.043 | M33: =D33-I33 -> 1
C34: 750 ml | E34: =(('[1]PURCHASE COST'!D33/12)+(('[1]PURCHASE COST'!D33/12)*3.87%))*D34 -> 0 | H34: 750 ml | J34: =(D34+G34)-I34 -> 0 | K34: =(('[1]PURCHASE COST'!D33/12)+(('[1]PURCHASE COST'!D33/12)*3.87%))*I34 -> 0 | M34: =D34-I34 -> 0
C35: 500 ml | E35: =(('[1]PURCHASE COST'!D34/18)+(('[1]PURCHASE COST'!D34/18)*3.87%))*D35 -> 0 | H35: 500 ml | J35: =(D35+G35)-I35 -> 0 | K35: =(('[1]PURCHASE COST'!D34/18)+(('[1]PURCHASE COST'!D34/18)*3.87%))*I35 -> 0 | M35: =D35-I35 -> 0
C36: 375 ml | D36: 25 | E36: =(('[1]PURCHASE COST'!D35/24)+(('[1]PURCHASE COST'!D35/24)*3.87%))*D36 -> 7682.0521 | H36: 375 ml | I36: 25 | J36: =(D36+G36)-I36 -> 0 | K36: =(('[1]PURCHASE COST'!D35/24)+(('[1]PURCHASE COST'!D35/24)*3.87%))*I36 -> 7682.0521 | M36: =D36-I36 -> 0
C37: 60 ml | D37: 9.5 | E37: =((('[1]PURCHASE COST'!D32/9)+(('[1]PURCHASE COST'!D32/9)*3.87%))/16.5)*D37 -> 446.53608 | H37: 60 ml | I37: 13 | J37: =((((D33+G33)-I33)*16.5)+D37)-I37 -> 13 | K37: =((('[1]PURCHASE COST'!D32/9)+(('[1]PURCHASE COST'!D32/9)*3.87%))/16.5)*I37 -> 611.04937
A38: 8 | B38: OFFICER CHOICE BRANDY | C38: 1000 ml | D38: 14 | E38: =(('[1]PURCHASE COST'!D37/9)+(('[1]PURCHASE COST'!D37/9)*3.87%))*D38 -> 12150.482 | F38: =SUM(E38:E42) -> 12387.179 | H38: 1000 ml | I38: 13 | K38: =(('[1]PURCHASE COST'!D37/9)+(('[1]PURCHASE COST'!D37/9)*3.87%))*I38 -> 11282.59 | L38: =K38+K39+K40+K41+K42 -> 11650.787 | M38: =D38-I38 -> 1
C39: 750 ml | E39: =(('[1]PURCHASE COST'!D38/12)+(('[1]PURCHASE COST'!D38/12)*3.87%))*D39 -> 0 | H39: 750 ml | J39: =(D39+G39)-I39 -> 0 | K39: =(('[1]PURCHASE COST'!D38/12)+(('[1]PURCHASE COST'!D38/12)*3.87%))*I39 -> 0 | M39: =D39-I39 -> 0
C40: 500 ml | E40: =(('[1]PURCHASE COST'!D39/18)+(('[1]PURCHASE COST'!D39/18)*3.87%))*D40 -> 0 | H40: 500 ml | J40: =(D40+G40)-I40 -> 0 | K40: =(('[1]PURCHASE COST'!D39/18)+(('[1]PURCHASE COST'!D39/18)*3.87%))*I40 -> 0 | M40: =D40-I40 -> 0
C41: 375 ml | E41: =(('[1]PURCHASE COST'!D40/24)+(('[1]PURCHASE COST'!D40/24)*3.87%))*D41 -> 0 | H41: 375 ml | J41: =(D41+G41)-I41 -> 0 | K41: =(('[1]PURCHASE COST'!D40/24)+(('[1]PURCHASE COST'!D40/24)*3.87%))*I41 -> 0 | M41: =D41-I41 -> 0
...

Sheet PRODUCT PRICE
A1: SL.No | B1: PARTICULARS | C1: VOLUME | D1: PURCHASE COST (per case)
A2: 1 | B2: CEASAR BRANDY | C2: 1000 ml
C3: 750 ml | D3: 13420
C4: 500 ml
C5: 375 ml
C6: 60 ml
A7: 2 | B7: M.C BRANDY | C7: 1000 ml | D7: 6720
C8: 750 ml
C9: 500 ml | D9: 6600
C10: 375 ml
C11: 60 ml
A12: 3 | B12: MGM ORANGE VODKA | C12: 1000 ml | D12: 6420
C13: 750 ml | D13: 7160
C14: 500 ml | D14: 6500
C15: 375 ml | D15: 7000
C16: 60 ml
A17: 4 | B17: MANSION HOUSE BRANDY | C17: 1000 ml | D17: 8240
C18: 750 ml | D18: 10520
C19: 500 ml | D19: 8640
C20: 375 ml | D20: 10620
C21: 60 ml
A22: 5 | B22: OLD CASK RUM | C22: 1000 ml | D22: 6620
C23: 750 ml
C24: 500 ml | D24: 6500
C25: 375 ml | D25: 6900
C26: 60 ml
A27: 6 | B27: CR. NEPOLEAN BRANDY | C27: 1000 ml | D27: 7420
C28: 750 ml | D28: 7960
C29: 500 ml | D29: 7600
C30: 375 ml
C31: 60 ml
A32: 7 | B32: HONEY BEE BRANDY | C32: 1000 ml | D32: 6720
C33: 750 ml
C34: 500 ml | D34: 6600
C35: 375 ml | D35: 7100
C36: 60 ml
A37: 8 | B37: OFFICER CHOICE BRANDY | C37: 1000 ml | D37: 7520
C38: 750 ml | D38: 8260
C39: 500 ml | D39: 7500
C40: 375 ml | D40: 8500
...
